ERROR:root:Exception in on_message.
Traceback (most recent call last):
  File "mqtt_opc_ua_link.py", line 74, in on_received_mqtt_message
    setChildrenRecursive(receivedObject, topLevelObject.get_children())
  File "/usr/local/lib/python3.8/site-packages/opcua/common/node.py", line 314, in get_children
    return self.get_referenced_nodes(refs, ua.BrowseDirection.Forward, nodeclassmask)
  File "/usr/local/lib/python3.8/site-packages/opcua/common/node.py", line 388, in get_referenced_nodes
    references = self.get_references(refs, direction, nodeclassmask, includesubtypes)
  File "/usr/local/lib/python3.8/site-packages/opcua/common/node.py", line 367, in get_references
    results = self.server.browse(params)
  File "/usr/local/lib/python3.8/site-packages/opcua/client/ua_client.py", line 317, in browse
    data = self._uasocket.send_request(request)
  File "/usr/local/lib/python3.8/site-packages/opcua/client/ua_client.py", line 81, in send_request
    future = self._send_request(request, callback, timeout, message_type)
  File "/usr/local/lib/python3.8/site-packages/opcua/client/ua_client.py", line 72, in _send_request
    self._socket.write(msg)
  File "/usr/local/lib/python3.8/site-packages/opcua/common/utils.py", line 118, in write
    self.socket.sendall(data)
OSError: [Errno 9] Bad file descriptor
    rc = self._send_publish(
  File "/usr/local/lib/python3.8/site-packages/paho/mqtt/client.py", line 2580, in _send_publish
    return self._packet_queue(PUBLISH, packet, mid, qos, info)
  File "/usr/local/lib/python3.8/site-packages/paho/mqtt/client.py", line 2937, in _packet_queue